<?xml version="1.0"?> <!--Declare XML Version  

typical value "1.0"--> 

<robot name="robot_sim"> 

    <link name="base_link">
        <visual>
            <origin xyz="0 0 0" rpy="0 0 0"/>
            <geometry>
                <box size="0.1 0.1 0.1"/>
            </geometry>
            <material name="base_link material"> 
                <color rgba="1.0 1.0 1.0 0.0"/>
            </material>
        </visual>

        <collision>
            <origin xyz="0 0 0" rpy="0 0 0"/>
            <geometry>
                <box size="0.1 0.1 0.1"/>
            </geometry>

        </collision>

        <inertial>
            <mass value="1"/>
            <origin xyz="0 0 0" rpy="0 0 0"/>
            <inertia ixx="0.1" ixy="0.0" ixz="0.0" iyy="0.1" iyz="0.0" izz="0.1"/>
        </inertial>
    </link>


    <link name="chassis"> 
        <visual>
            <origin xyz="0 0 0.04530" rpy="1.57079632679 0 1.57079632679"/>
            <geometry>
                <mesh filename="package://puzzlebot_sim/models/MCR2_1000_13_Chassis.stl"/>
            </geometry>
        </visual>
        
        <collision>
            <origin xyz="0 0 0.04530" rpy="1.57079632679 0 1.57079632679"/>
            <geometry>
                <mesh filename="package://puzzlebot_sim/models/MCR2_1000_13_Chassis.stl"/>
            </geometry>
        </collision>
        
        <inertial>
            <origin xyz="0 0 0.04530" rpy="1.57079632679 0 1.57079632679"/>
            <mass value="0.01"/>
            <inertia ixx="7.58333333333e-06" ixy="0.0" ixz="0.0" iyy="7.58333333333e-06" iyz="0.0" izz="1.25e-05"/>
        </inertial>
    
    </link> 

    <link name="wl_link"> 
        <visual> 
            <origin xyz="0 0 0" rpy="0 0 0"/> 
            <geometry>
                <mesh filename="package://puzzlebot_sim/models/Wheel.stl"/>
            </geometry>
        </visual> 

        <collision> 
            <origin xyz="0 0 0" rpy="0 0 0"/> 
            <geometry>
                <mesh filename="package://puzzlebot_sim/models/Wheel.stl"/>
            </geometry>
        </collision> 
    </link> 

    <link name="wr_link"> 
        <visual> 
            <origin xyz="0 0 0" rpy="0 0 0"/> 
            <geometry>
                <mesh filename="package://puzzlebot_sim/models/Wheel.stl"/>
            </geometry>
        </visual> 

        <collision> 
            <origin xyz="0 0 0" rpy="0 0 0"/> 
            <geometry>
                <mesh filename="package://puzzlebot_sim/models/Wheel.stl"/>
            </geometry>
        </collision> 
    </link> 


    <joint name="chassis_joint" type="fixed"> 
        <parent link="base_link"/> 
        <child link="chassis"/>
        <origin xyz="0 0 0" rpy="0 0 0"/> 
    </joint> 

    <joint name="wl_joint" type="continuous"> 
        <parent link="chassis"/> 
        <child link="wl_link"/>
        <origin xyz="0.05 0.0955 0.05" rpy="0 1.57079632679 -1.57079632679"/> 
        <axis xyz="0 0 1 " /> 
    </joint> 

    <joint name="wr_joint" type="continuous"> 
        <parent link="chassis"/> 
        <child link="wr_link"/>
        <origin xyz="0.05 -0.0955 0.05" rpy="0 1.57079632679 1.57079632679"/> 
        <axis xyz="0 0 1 " /> 
    </joint> 


</robot>